Traceback (most recent call last):
  File "/Users/emanuelevivoli/miniconda3/lib/python3.7/site-packages/jupyter_cache/executors/utils.py", line 56, in single_nb_execution
    record_timing=False,
  File "/Users/emanuelevivoli/miniconda3/lib/python3.7/site-packages/nbclient/client.py", line 1204, in execute
    return NotebookClient(nb=nb, resources=resources, km=km, **kwargs).execute()
  File "/Users/emanuelevivoli/miniconda3/lib/python3.7/site-packages/nbclient/util.py", line 84, in wrapped
    return just_run(coro(*args, **kwargs))
  File "/Users/emanuelevivoli/miniconda3/lib/python3.7/site-packages/nbclient/util.py", line 62, in just_run
    return loop.run_until_complete(coro)
  File "/Users/emanuelevivoli/miniconda3/lib/python3.7/asyncio/base_events.py", line 579, in run_until_complete
    return future.result()
  File "/Users/emanuelevivoli/miniconda3/lib/python3.7/site-packages/nbclient/client.py", line 664, in async_execute
    cell, index, execution_count=self.code_cells_executed + 1
  File "/Users/emanuelevivoli/miniconda3/lib/python3.7/site-packages/nbclient/client.py", line 965, in async_execute_cell
    await self._check_raise_for_error(cell, cell_index, exec_reply)
  File "/Users/emanuelevivoli/miniconda3/lib/python3.7/site-packages/nbclient/client.py", line 862, in _check_raise_for_error
    raise CellExecutionError.from_cell_and_msg(cell, exec_reply_content)
nbclient.exceptions.CellExecutionError: An error occurred while executing the following cell:
------------------
import numpy as np
from sklearn.ensemble import RandomForestClassifier

# Load the data
X = np.load("fraud_data.npy")
y = np.load("fraud_labels.npy")

# Split the data into training and testing sets
X_train, X_test, y_train, y_test = train_test_split(X, y, test_size=0.2)

# Train the model
model = RandomForestClassifier()
model.fit(X_train, y_train)

# Evaluate the model on the test set
accuracy = model.score(X_test, y_test)
print("Test set accuracy: {:.2f}".format(accuracy))
------------------

[0;31m---------------------------------------------------------------------------[0m
[0;31mFileNotFoundError[0m                         Traceback (most recent call last)
[0;32m/var/folders/yw/39qgg96x2451prd0f9qrtbzr0000gn/T/ipykernel_6542/835039378.py[0m in [0;36m<module>[0;34m[0m
[1;32m      3[0m [0;34m[0m[0m
[1;32m      4[0m [0;31m# Load the data[0m[0;34m[0m[0;34m[0m[0;34m[0m[0m
[0;32m----> 5[0;31m [0mX[0m [0;34m=[0m [0mnp[0m[0;34m.[0m[0mload[0m[0;34m([0m[0;34m"fraud_data.npy"[0m[0;34m)[0m[0;34m[0m[0;34m[0m[0m
[0m[1;32m      6[0m [0my[0m [0;34m=[0m [0mnp[0m[0;34m.[0m[0mload[0m[0;34m([0m[0;34m"fraud_labels.npy"[0m[0;34m)[0m[0;34m[0m[0;34m[0m[0m
[1;32m      7[0m [0;34m[0m[0m

[0;32m~/miniconda3/lib/python3.7/site-packages/numpy/lib/npyio.py[0m in [0;36mload[0;34m(file, mmap_mode, allow_pickle, fix_imports, encoding)[0m
[1;32m    415[0m             [0mown_fid[0m [0;34m=[0m [0;32mFalse[0m[0;34m[0m[0;34m[0m[0m
[1;32m    416[0m         [0;32melse[0m[0;34m:[0m[0;34m[0m[0;34m[0m[0m
[0;32m--> 417[0;31m             [0mfid[0m [0;34m=[0m [0mstack[0m[0;34m.[0m[0menter_context[0m[0;34m([0m[0mopen[0m[0;34m([0m[0mos_fspath[0m[0;34m([0m[0mfile[0m[0;34m)[0m[0;34m,[0m [0;34m"rb"[0m[0;34m)[0m[0;34m)[0m[0;34m[0m[0;34m[0m[0m
[0m[1;32m    418[0m             [0mown_fid[0m [0;34m=[0m [0;32mTrue[0m[0;34m[0m[0;34m[0m[0m
[1;32m    419[0m [0;34m[0m[0m

[0;31mFileNotFoundError[0m: [Errno 2] No such file or directory: 'fraud_data.npy'
FileNotFoundError: [Errno 2] No such file or directory: 'fraud_data.npy'

