Traceback (most recent call last):
  File "/Users/emanuelevivoli/miniconda3/lib/python3.7/site-packages/jupyter_cache/executors/utils.py", line 56, in single_nb_execution
    record_timing=False,
  File "/Users/emanuelevivoli/miniconda3/lib/python3.7/site-packages/nbclient/client.py", line 1204, in execute
    return NotebookClient(nb=nb, resources=resources, km=km, **kwargs).execute()
  File "/Users/emanuelevivoli/miniconda3/lib/python3.7/site-packages/nbclient/util.py", line 84, in wrapped
    return just_run(coro(*args, **kwargs))
  File "/Users/emanuelevivoli/miniconda3/lib/python3.7/site-packages/nbclient/util.py", line 62, in just_run
    return loop.run_until_complete(coro)
  File "/Users/emanuelevivoli/miniconda3/lib/python3.7/asyncio/base_events.py", line 579, in run_until_complete
    return future.result()
  File "/Users/emanuelevivoli/miniconda3/lib/python3.7/site-packages/nbclient/client.py", line 664, in async_execute
    cell, index, execution_count=self.code_cells_executed + 1
  File "/Users/emanuelevivoli/miniconda3/lib/python3.7/site-packages/nbclient/client.py", line 965, in async_execute_cell
    await self._check_raise_for_error(cell, cell_index, exec_reply)
  File "/Users/emanuelevivoli/miniconda3/lib/python3.7/site-packages/nbclient/client.py", line 862, in _check_raise_for_error
    raise CellExecutionError.from_cell_and_msg(cell, exec_reply_content)
nbclient.exceptions.CellExecutionError: An error occurred while executing the following cell:
------------------
import pandas as pd
import seaborn as sns

# Load customer data
customers = pd.read_csv("customer_data.csv")

# View the first few rows
print(customers.head())

# Plot a scatterplot of customer spending vs. age
sns.scatterplot(x="age", y="spending", data=customers)
------------------

[0;31m---------------------------------------------------------------------------[0m
[0;31mModuleNotFoundError[0m                       Traceback (most recent call last)
[0;32m/var/folders/yw/39qgg96x2451prd0f9qrtbzr0000gn/T/ipykernel_6551/4145983809.py[0m in [0;36m<module>[0;34m[0m
[1;32m      1[0m [0;32mimport[0m [0mpandas[0m [0;32mas[0m [0mpd[0m[0;34m[0m[0;34m[0m[0m
[0;32m----> 2[0;31m [0;32mimport[0m [0mseaborn[0m [0;32mas[0m [0msns[0m[0;34m[0m[0;34m[0m[0m
[0m[1;32m      3[0m [0;34m[0m[0m
[1;32m      4[0m [0;31m# Load customer data[0m[0;34m[0m[0;34m[0m[0;34m[0m[0m
[1;32m      5[0m [0mcustomers[0m [0;34m=[0m [0mpd[0m[0;34m.[0m[0mread_csv[0m[0;34m([0m[0;34m"customer_data.csv"[0m[0;34m)[0m[0;34m[0m[0;34m[0m[0m

[0;31mModuleNotFoundError[0m: No module named 'seaborn'
ModuleNotFoundError: No module named 'seaborn'

