Traceback (most recent call last):
  File "/Users/emanuelevivoli/miniconda3/lib/python3.7/site-packages/jupyter_cache/executors/utils.py", line 56, in single_nb_execution
    record_timing=False,
  File "/Users/emanuelevivoli/miniconda3/lib/python3.7/site-packages/nbclient/client.py", line 1204, in execute
    return NotebookClient(nb=nb, resources=resources, km=km, **kwargs).execute()
  File "/Users/emanuelevivoli/miniconda3/lib/python3.7/site-packages/nbclient/util.py", line 84, in wrapped
    return just_run(coro(*args, **kwargs))
  File "/Users/emanuelevivoli/miniconda3/lib/python3.7/site-packages/nbclient/util.py", line 62, in just_run
    return loop.run_until_complete(coro)
  File "/Users/emanuelevivoli/miniconda3/lib/python3.7/asyncio/base_events.py", line 579, in run_until_complete
    return future.result()
  File "/Users/emanuelevivoli/miniconda3/lib/python3.7/site-packages/nbclient/client.py", line 664, in async_execute
    cell, index, execution_count=self.code_cells_executed + 1
  File "/Users/emanuelevivoli/miniconda3/lib/python3.7/site-packages/nbclient/client.py", line 965, in async_execute_cell
    await self._check_raise_for_error(cell, cell_index, exec_reply)
  File "/Users/emanuelevivoli/miniconda3/lib/python3.7/site-packages/nbclient/client.py", line 862, in _check_raise_for_error
    raise CellExecutionError.from_cell_and_msg(cell, exec_reply_content)
nbclient.exceptions.CellExecutionError: An error occurred while executing the following cell:
------------------
import numpy as np

# Generate some random data
data = np.random.normal(5, 2, 100)

# Calculate mean, median, mode, range, and standard deviation
mean = np.mean(data)
median = np.median(data)
mode = stats.mode(data)
range = np.max(data) - np.min(data)
std = np.std(data)

print(f"Mean: {mean:.2f}")
print(f"Median: {median:.2f}")
print(f"Mode: {mode[0][0]:.2f}")
print(f"Range: {range:.2f}")
print(f"Standard deviation: {std:.2f}")
------------------

[0;31m---------------------------------------------------------------------------[0m
[0;31mNameError[0m                                 Traceback (most recent call last)
[0;32m/var/folders/yw/39qgg96x2451prd0f9qrtbzr0000gn/T/ipykernel_6449/1702991985.py[0m in [0;36m<module>[0;34m[0m
[1;32m      7[0m [0mmean[0m [0;34m=[0m [0mnp[0m[0;34m.[0m[0mmean[0m[0;34m([0m[0mdata[0m[0;34m)[0m[0;34m[0m[0;34m[0m[0m
[1;32m      8[0m [0mmedian[0m [0;34m=[0m [0mnp[0m[0;34m.[0m[0mmedian[0m[0;34m([0m[0mdata[0m[0;34m)[0m[0;34m[0m[0;34m[0m[0m
[0;32m----> 9[0;31m [0mmode[0m [0;34m=[0m [0mstats[0m[0;34m.[0m[0mmode[0m[0;34m([0m[0mdata[0m[0;34m)[0m[0;34m[0m[0;34m[0m[0m
[0m[1;32m     10[0m [0mrange[0m [0;34m=[0m [0mnp[0m[0;34m.[0m[0mmax[0m[0;34m([0m[0mdata[0m[0;34m)[0m [0;34m-[0m [0mnp[0m[0;34m.[0m[0mmin[0m[0;34m([0m[0mdata[0m[0;34m)[0m[0;34m[0m[0;34m[0m[0m
[1;32m     11[0m [0mstd[0m [0;34m=[0m [0mnp[0m[0;34m.[0m[0mstd[0m[0;34m([0m[0mdata[0m[0;34m)[0m[0;34m[0m[0;34m[0m[0m

[0;31mNameError[0m: name 'stats' is not defined
NameError: name 'stats' is not defined

