Traceback (most recent call last):
  File "/Users/emanuelevivoli/miniconda3/lib/python3.7/site-packages/jupyter_cache/executors/utils.py", line 56, in single_nb_execution
    record_timing=False,
  File "/Users/emanuelevivoli/miniconda3/lib/python3.7/site-packages/nbclient/client.py", line 1204, in execute
    return NotebookClient(nb=nb, resources=resources, km=km, **kwargs).execute()
  File "/Users/emanuelevivoli/miniconda3/lib/python3.7/site-packages/nbclient/util.py", line 84, in wrapped
    return just_run(coro(*args, **kwargs))
  File "/Users/emanuelevivoli/miniconda3/lib/python3.7/site-packages/nbclient/util.py", line 62, in just_run
    return loop.run_until_complete(coro)
  File "/Users/emanuelevivoli/miniconda3/lib/python3.7/asyncio/base_events.py", line 579, in run_until_complete
    return future.result()
  File "/Users/emanuelevivoli/miniconda3/lib/python3.7/site-packages/nbclient/client.py", line 664, in async_execute
    cell, index, execution_count=self.code_cells_executed + 1
  File "/Users/emanuelevivoli/miniconda3/lib/python3.7/site-packages/nbclient/client.py", line 965, in async_execute_cell
    await self._check_raise_for_error(cell, cell_index, exec_reply)
  File "/Users/emanuelevivoli/miniconda3/lib/python3.7/site-packages/nbclient/client.py", line 862, in _check_raise_for_error
    raise CellExecutionError.from_cell_and_msg(cell, exec_reply_content)
nbclient.exceptions.CellExecutionError: An error occurred while executing the following cell:
------------------
from math import sqrt

class Point:
  def __init__(self, x, y):
    self.x = x
    self.y = y

  def distance_to_origin(self):
    return sqrt(self.x**2 + self.y**2)

class Line:
  def __init__(self, point1, point2):
    self.point1 = point1
    self.point2 = point2

  def length(self):
    return point1.distance_to_origin(point2)

point1 = Point(3, 4)
point2 = Point(5, 6)
line = Line(point1, point2)
print(line.length())  # Output: 2.8284271247461903
------------------

[0;31m---------------------------------------------------------------------------[0m
[0;31mTypeError[0m                                 Traceback (most recent call last)
[0;32m/var/folders/yw/39qgg96x2451prd0f9qrtbzr0000gn/T/ipykernel_8122/1391703768.py[0m in [0;36m<module>[0;34m[0m
[1;32m     20[0m [0mpoint2[0m [0;34m=[0m [0mPoint[0m[0;34m([0m[0;36m5[0m[0;34m,[0m [0;36m6[0m[0;34m)[0m[0;34m[0m[0;34m[0m[0m
[1;32m     21[0m [0mline[0m [0;34m=[0m [0mLine[0m[0;34m([0m[0mpoint1[0m[0;34m,[0m [0mpoint2[0m[0;34m)[0m[0;34m[0m[0;34m[0m[0m
[0;32m---> 22[0;31m [0mprint[0m[0;34m([0m[0mline[0m[0;34m.[0m[0mlength[0m[0;34m([0m[0;34m)[0m[0;34m)[0m  [0;31m# Output: 2.8284271247461903[0m[0;34m[0m[0;34m[0m[0m
[0m
[0;32m/var/folders/yw/39qgg96x2451prd0f9qrtbzr0000gn/T/ipykernel_8122/1391703768.py[0m in [0;36mlength[0;34m(self)[0m
[1;32m     15[0m [0;34m[0m[0m
[1;32m     16[0m   [0;32mdef[0m [0mlength[0m[0;34m([0m[0mself[0m[0;34m)[0m[0;34m:[0m[0;34m[0m[0;34m[0m[0m
[0;32m---> 17[0;31m     [0;32mreturn[0m [0mpoint1[0m[0;34m.[0m[0mdistance_to_origin[0m[0;34m([0m[0mpoint2[0m[0;34m)[0m[0;34m[0m[0;34m[0m[0m
[0m[1;32m     18[0m [0;34m[0m[0m
[1;32m     19[0m [0mpoint1[0m [0;34m=[0m [0mPoint[0m[0;34m([0m[0;36m3[0m[0;34m,[0m [0;36m4[0m[0;34m)[0m[0;34m[0m[0;34m[0m[0m

[0;31mTypeError[0m: distance_to_origin() takes 1 positional argument but 2 were given
TypeError: distance_to_origin() takes 1 positional argument but 2 were given

